Workbook

Sheet Components
B2: Alfa AWUS036ACH Dual Band USB Adaptor AC1200
B3: Raspberry Pi 4B
B4: Radiomaster AG01 NANO
B5: Raspberry Pi Pico 2
B6: Large switch
B7: Small switch
B8: Red LED
B9: Green LED
B10: Yellow LED
B11: XT30 socket
B12: XT60 socket
B13: Picam V3
... B17: MATEK MICRO BEC 6-60V TO 5V/9V/12V

Sheet Pins
B3: =Components!B$3 -> Raspberry Pi 4B | C3: Pin-1 3.3V
C4: Pin-4 5V
C5: Pin-6 Gnd
C6: Pin-8 TX GPIO14
C7: Pin-10 RX GPIO15
C8: Pin-29 GPIO5
C9: Pin-31 GPIO6
C10: Pin-33 GPIO13
C11: Pin-34 Gnd
C12: Pin-35 GPIO19
C13: Pin-37 GPIO26
C14: Pin-38 GPIO20
C15: Pin-40 GPIO21
B16: =Components!B$15 -> USB-A connector | C16: 5V
C17: D-
C18: D+
C19: Gnd
B20: =Components!B$16 -> USB-C connector | C20: 5V
C21: D-
C22: D+
C23: Gnd
B24: =Components!B$14 -> 470uF capacitor | C24: Plus
C25: Minus
B26: =Components!B$17 -> MATEK MICRO BEC 6-60V TO 5V/9V/12V | C26: V-in
C27: Gnd1
C28: Gnd2
C29: V-out
B30: =Components!B$4 -> Radiomaster AG01 NANO | C30: Horiz 5V
C31: Horiz Gnd
C32: Horiz Signal
C33: Vert 5V
C34: Vert Gnd
C35: Vert Signal
B36: =Components!B$8 -> Red LED | C36: Plus
C37: Minus
B38: =Components!B$9 -> Green LED | C38: Plus
C39: Minus
B40: =Components!B$10 -> Yellow LED | C40: Plus
C41: Minus
B42: =Components!B$6 -> Large switch | C42: Top
...

Sheet Ground unit components
B2: Component | C2: Type
B3: RPi | C3: =Components!B$3 -> Raspberry Pi 4B
B4: Radio | C4: =Components!B$2 -> Alfa AWUS036ACH Dual Band USB Adaptor AC1200
B5: Left Joystick | C5: =Components!B$4 -> Radiomaster AG01 NANO
B6: Right Joystick | C6: =Components!B$4 -> Radiomaster AG01 NANO
B7: Left mode switch | C7: =Components!B$6 -> Large switch
B8: Right mode switch | C8: =Components!B$6 -> Large switch
B9: Left spare switch | C9: =Components!B$7 -> Small switch
B10: Right spare switch | C10: =Components!B$7 -> Small switch
B11: Left kill switch | C11: =Components!B$7 -> Small switch
B12: Right kill switch | C12: =Components!B$7 -> Small switch
B13: Left IO processor | C13: =Components!B$5 -> Raspberry Pi Pico 2
B14: Right IO processor | C14: =Components!B$5 -> Raspberry Pi Pico 2
B15: Large power connector | C15: =Components!B$12 -> XT60 socket
B16: Small power connector | C16: =Components!B$11 -> XT30 socket
B17: Capacitor | C17: =Components!B$14 -> 470uF capacitor
B18: RPi USB connector | C18: =Components!B$15 -> USB-A connector
B19: Radio USB connector | C19: =Components!B$16 -> USB-C connector
B20: BEC | C20: =Components!B$17 -> MATEK MICRO BEC 6-60V TO 5V/9V/12V
B21: Power-on LED | C21: =Components!$B$8 -> Red LED
B22: RC LED | C22: =Components!$B$9 -> Green LED
B23: Mavlink LED | C23: =Components!$B$9 -> Green LED
B24: RSSI LED1 | C24: =Components!$B$10 -> Yellow LED
B25: RSSI LED2 | C25: =Components!$B$10 -> Yellow LED
B26: RSSI LED3 | C26: =Components!$B$10 -> Yellow LED
B27: RSSI LED4 | C27: =Components!$B$10 -> Yellow LED
B28: RSSI LED5 | C28: =Components!$B$10 -> Yellow LED
B29: XT30 Power | C29: =Components!$B$11 -> XT30 socket
B30: XT60 Power | C30: =Components!$B$12 -> XT60 socket

Sheet Ground unit connections
B1: From | E1: To
B2: Component | C2: Pin | E2: Component | F2: Pin
B3: ='Ground unit components'!$B$29 -> XT30 Power | C3: =Pins!$C$63 -> Plus | E3: ='Ground unit components'!$B$30 -> XT60 Power | F3: =Pins!$C$65 -> Plus
C4: =Pins!$C$64 -> Minus | E4: ='Ground unit components'!$B$30 -> XT60 Power | F4: =Pins!$C$66 -> Minus
B5: ='Ground unit components'!$B$30 -> XT60 Power | C5: =Pins!$C$65 -> Plus | E5: ='Ground unit components'!$B$20 -> BEC | F5: =Pins!$C$26 -> V-in
C6: =Pins!$C$66 -> Minus | E6: ='Ground unit components'!$B$20 -> BEC | F6: =Pins!$C$27 -> Gnd1
B7: ='Ground unit components'!$B$20 -> BEC | C7: =Pins!$C$27 -> Gnd1 | E7: ='Ground unit components'!$B$20 -> BEC | F7: =Pins!$C$28 -> Gnd2
C8: =Pins!$C$29 -> V-out | E8: ='Ground unit components'!$B$3 -> RPi | F8: =Pins!$C$4 -> Pin-4 5V
C9: =Pins!$C$29 -> V-out | E9: ='Ground unit components'!$B$19 -> Radio USB connector | F9: =Pins!C16 -> 5V
C10: =Pins!$C$29 -> V-out | E10: ='Ground unit components'!$B$13 -> Left IO processor | F10: =C36 -> Vbus
C11: =Pins!$C$29 -> V-out | E11: ='Ground unit components'!$B$14 -> Right IO processor | F11: =Pins!$C$48 -> Vbus
C12: =Pins!$C$28 -> Gnd2 | E12: ='Ground unit components'!$B$3 -> RPi | F12: =Pins!$C$5 -> Pin-6 Gnd
C13: =Pins!$C$28 -> Gnd2 | E13: ='Ground unit components'!$B$19 -> Radio USB connector | F13: =Pins!C19 -> Gnd
C14: =Pins!$C$28 -> Gnd2 | E14: ='Ground unit components'!$B$13 -> Left IO processor | F14: =Pins!$C$49 -> GND1
C15: =Pins!$C$28 -> Gnd2 | E15: ='Ground unit components'!$B$14 -> Right IO processor | F15: =Pins!$C$49 -> GND1
B16: ='Ground unit components'!B3 -> RPi | C16: =Pins!$C$4 -> Pin-4 5V | E16: ='Ground unit components'!$B$13 -> Left IO processor | F16: =Pins!$C$48 -> Vbus
C17: =Pins!$C$4 -> Pin-4 5V | E17: ='Ground unit components'!$B$14 -> Right IO processor | F17: =Pins!$C$48 -> Vbus
C18: =Pins!$C$5 -> Pin-6 Gnd | E18: ='Ground unit components'!$B$13 -> Left IO processor | F18: =Pins!$C$49 -> GND1
C19: =Pins!$C$5 -> Pin-6 Gnd | E19: ='Ground unit components'!$B$14 -> Right IO processor | F19: =Pins!$C$49 -> GND1
C20: =Pins!$C$14 -> Pin-38 GPIO20 | E20: ='Ground unit components'!$B$22 -> RC LED | F20: =Pins!$C$38 -> Plus
C21: =Pins!$C$15 -> Pin-40 GPIO21 | E21: ='Ground unit components'!$B$23 -> Mavlink LED | F21: =Pins!$C$38 -> Plus
C22: =Pins!C8 -> Pin-29 GPIO5 | E22: ='Ground unit components'!B24 -> RSSI LED1 | F22: =Pins!$C$40 -> Plus
C23: =Pins!C9 -> Pin-31 GPIO6 | E23: ='Ground unit components'!B25 -> RSSI LED2 | F23: =Pins!$C$40 -> Plus
C24: =Pins!C10 -> Pin-33 GPIO13 | E24: ='Ground unit components'!B26 -> RSSI LED3 | F24: =Pins!$C$40 -> Plus
C25: =Pins!C11 -> Pin-34 Gnd | E25: ='Ground unit components'!B27 -> RSSI LED4 | F25: =Pins!$C$40 -> Plus
C26: =Pins!C12 -> Pin-35 GPIO19 | E26: ='Ground unit components'!B28 -> RSSI LED5 | F26: =Pins!$C$40 -> Plus
C27: =Components!$B$15 -> USB-A connector | E27: ='Ground unit components'!B18 -> RPi USB connector
B28: ='Ground unit components'!$B$4 -> Radio | C28: =Components!B16 -> USB-C connector | E28: ='Ground unit components'!B19 -> Radio USB connector
B29: ='Ground unit components'!$B$13 -> Left IO processor | C29: =Pins!$C$49 -> GND1 | E29: ='Ground unit components'!$B$5 -> Left Joystick | F29: =Pins!$C$34 -> Vert Gnd
E30: ='Ground unit components'!$B$5 -> Left Joystick | F30: =Pins!$C$31 -> Horiz Gnd
E31: ='Ground unit components'!$B$7 -> Left mode switch | F31: =Pins!$C$43 -> Centre
E32: ='Ground unit components'!$B$9 -> Left spare switch | F32: =Pins!$C$46 -> Centre
E33: ='Ground unit components'!$B$11 -> Left kill switch | F33: =Pins!$C$46 -> Centre
C34: =Pins!$C$60 -> GP13 | E34: N/A | F34: N/C
C35: =Pins!$C$61 -> GP0 | E35: ='Ground unit components'!$B$13 -> Left IO processor | F35: =Pins!$C$62 -> GP1
C36: =Pins!$C$48 -> Vbus | E36: ='Ground unit components'!$B$13 -> Left IO processor | F36: =Pins!$C$52 -> ADC_REF
C37: =Pins!$C$49 -> GND1 | E37: ='Ground unit components'!$B$13 -> Left IO processor | F37: =Pins!$C$53 -> AGND
B38: ='Ground unit components'!$B$5 -> Left Joystick | C38: =Pins!$C$32 -> Horiz Signal | E38: ='Ground unit components'!$B$13 -> Left IO processor | F38: =Pins!$C$55 -> GP26_A0
C39: =Pins!$C$35 -> Vert Signal | E39: ='Ground unit components'!$B$13 -> Left IO processor | F39: =Pins!$C$54 -> GP27_A1
B40: ='Ground unit components'!$B$7 -> Left mode switch | C40: =Pins!$C$42 -> Top | E40: ='Ground unit components'!$B$13 -> Left IO processor | F40: =Pins!$C$58 -> GP19
...

Sheet Air unit components
B2: Component | C2: Type
B3: RPi | C3: =Components!B$3 -> Raspberry Pi 4B
B4: Radio | C4: =Components!B$2 -> Alfa AWUS036ACH Dual Band USB Adaptor AC1200
B5: Small power connector | C5: =Components!B$11 -> XT30 socket
B6: Capacitor | C6: =Components!B$14 -> 470uF capacitor
B7: RPi USB connector | C7: =Components!B$15 -> USB-A connector
B8: Radio USB connector | C8: =Components!B$16 -> USB-C connector
B9: BEC | C9: =Components!B$17 -> MATEK MICRO BEC 6-60V TO 5V/9V/12V
B10: RC LED | C10: =Components!$B$9 -> Green LED
B11: Mavlink LED | C11: =Components!$B$9 -> Green LED
B12: Camera | C12: =Components!$B$13 -> Picam V3

Sheet Air unit connections
B2: From | E2: To
B3: Component | C3: Pin | E3: Component | F3: Pin
B4: ='Air unit components'!B5 -> Small power connector | C4: =Pins!$C$63 -> Plus | E4: ='Ground unit components'!$B$30 -> XT60 Power | F4: =Pins!$C$65 -> Plus
C5: =Pins!$C$64 -> Minus | E5: ='Ground unit components'!$B$30 -> XT60 Power | F5: =Pins!$C$66 -> Minus
B6: ='Air unit components'!B9 -> BEC | C6: =Pins!$C$27 -> Gnd1 | E6: ='Ground unit components'!$B$20 -> BEC | F6: =Pins!$C$28 -> Gnd2
C7: =Pins!$C$29 -> V-out | E7: ='Ground unit components'!$B$3 -> RPi | F7: =Pins!$C$4 -> Pin-4 5V
C8: =Pins!$C$29 -> V-out | E8: ='Ground unit components'!$B$19 -> Radio USB connector | F8: =Pins!C17 -> D-
C9: =Pins!$C$28 -> Gnd2 | E9: ='Ground unit components'!$B$3 -> RPi | F9: =Pins!$C$5 -> Pin-6 Gnd
C10: =Pins!$C$28 -> Gnd2 | E10: ='Ground unit components'!$B$19 -> Radio USB connector | F10: =Pins!C20 -> 5V
B11: ='Air unit components'!B3 -> RPi | C11: =Pins!$C$4 -> Pin-4 5V | E11: ='Ground unit components'!$B$13 -> Left IO processor | F11: =Pins!$C$48 -> Vbus
C12: =Pins!$C$4 -> Pin-4 5V | E12: ='Ground unit components'!$B$14 -> Right IO processor | F12: =Pins!$C$48 -> Vbus
C13: =Pins!$C$5 -> Pin-6 Gnd | E13: ='Ground unit components'!$B$13 -> Left IO processor | F13: =Pins!$C$49 -> GND1
C14: =Pins!$C$5 -> Pin-6 Gnd | E14: ='Ground unit components'!$B$14 -> Right IO processor | F14: =Pins!$C$49 -> GND1
C15: =Pins!$C$14 -> Pin-38 GPIO20 | E15: ='Ground unit components'!$B$22 -> RC LED | F15: =Pins!$C$38 -> Plus
C16: =Pins!$C$15 -> Pin-40 GPIO21 | E16: ='Ground unit components'!$B$23 -> Mavlink LED | F16: =Pins!$C$38 -> Plus
C17: =Pins!C9 -> Pin-31 GPIO6 | E17: ='Ground unit components'!B25 -> RSSI LED2 | F17: =Pins!$C$40 -> Plus
C18: =Pins!C10 -> Pin-33 GPIO13 | E18: ='Ground unit components'!B26 -> RSSI LED3 | F18: =Pins!$C$40 -> Plus
C19: =Pins!C11 -> Pin-34 Gnd | E19: ='Ground unit components'!B27 -> RSSI LED4 | F19: =Pins!$C$40 -> Plus
C20: =Pins!C12 -> Pin-35 GPIO19 | E20: ='Ground unit components'!B28 -> RSSI LED5 | F20: =Pins!$C$40 -> Plus
C21: =Pins!C13 -> Pin-37 GPIO26 | E21: ='Ground unit components'!B29 -> XT30 Power | F21: =Pins!$C$40 -> Plus
C22: =Components!$B$15 -> USB-A connector | E22: ='Air unit components'!B7 -> RPi USB connector
B23: ='Air unit components'!B4 -> Radio | C23: =Components!B16 -> USB-C connector | E23: =B24 -> Radio USB connector
B24: ='Ground unit components'!$B$19 -> Radio USB connector | C24: =Pins!$C$20 -> 5V | E24: ='Ground unit components'!$B$18 -> RPi USB connector | F24: =Pins!$C$16 -> 5V
C25: =Pins!$C$20 -> 5V | E25: ='Ground unit components'!$B$17 -> Capacitor | F25: =Pins!C25 -> Minus
C26: =Pins!C22 -> D+ | E26: ='Ground unit components'!$B$18 -> RPi USB connector | F26: =Pins!C18 -> D+
C27: =Pins!C23 -> Gnd | E27: ='Ground unit components'!$B$18 -> RPi USB connector | F27: =Pins!C19 -> Gnd
C28: =Pins!$C$23 -> Gnd | E28: ='Ground unit components'!$B$18 -> RPi USB connector | F28: =Pins!$C$19 -> Gnd
E29: ='Ground unit components'!$B$17 -> Capacitor | F29: =Pins!C26 -> V-in
B30: ='Air unit components'!B12 -> Camera
